<?xml version="1.0" ?>
<sdf version="1.6">
  <model name="glider_slocum">
    <static>false</static>
    
    <!-- Base link: Visual from slocum, collision from submarine (cylinder) -->
    <link name="base_link">
      <visual name="base_link_visual">
        <pose>0 0 0 0 0 0</pose>
        <geometry>
          <mesh>
            <scale>1.0 1.0 1.0</scale>
            <uri>file://models/glider_slocum/mesh/Slocum-Glider.dae</uri>
          </mesh>
        </geometry>
      </visual>
      <collision name="base_link_collision">
        <pose>0 0 0 0 0 0</pose>
        <geometry>
          <cylinder>
            <radius>0.2</radius>
            <length>2</length>
          </cylinder>
        </geometry>
      </collision>
      <inertial>
        <pose>0 0 0 0 0 0</pose>
        <!-- Use submarine's buoyant mass -->
        <mass>251.32741228718348</mass>
        <inertia>
          <ixx>86.28907821859966</ixx>
          <ixy>0</ixy>
          <ixz>0</ixz>
          <iyy>86.28907821859966</iyy>
          <iyz>0</iyz>
          <izz>5.026548245743671</izz>
        </inertia>
      </inertial>
    </link>
    
    <!-- Battery remains unchanged -->
    <link name="battery_link">
      <pose>0 0 0 0 0 0</pose>
      <inertial>
        <pose>0 0 0 0 0 0</pose>
        <mass>0.001</mass>
        <inertia>
          <ixx>1e-05</ixx>
          <ixy>0</ixy>
          <ixz>0</ixz>
          <iyy>1e-05</iyy>
          <iyz>0</iyz>
          <izz>1e-05</izz>
        </inertia>
      </inertial>
      <battery name="battery">
        <voltage>4.2</voltage>
      </battery>
    </link>
    
    <joint name="battery_joint" type="fixed">
      <pose>0 0 0 0 0 0</pose>
      <parent>base_link</parent>
      <child>battery_link</child>
    </joint>
    
    <!-- Propeller link: Visual from slocum -->
    <link name="propeller">
      <visual name="propeller_visual">
        <pose>0 0 0 0 0 0</pose>
        <geometry>
          <mesh>
            <scale>1.0 1.0 1.0</scale>
            <uri>file://models/glider_slocum/mesh/Slocum-Glider-Propeller.dae</uri>
          </mesh>
        </geometry>
      </visual>
      <collision name="propeller_collision">
        <pose>0 0 0 0 0 0</pose>
        <geometry>
          <mesh>
            <scale>1.0 1.0 1.0</scale>
            <uri>file://models/glider_slocum/mesh/Slocum-Glider-Propeller.dae</uri>
          </mesh>
        </geometry>
      </collision>
      <inertial>
        <pose>0 0 0 0 0 0</pose>
        <!-- Use submarine propeller inertial properties -->
        <mass>21.82</mass>
        <inertia>
          <ixx>0.45999415237916674</ixx>
          <ixy>0</ixy>
          <ixz>0</ixz>
          <iyy>0.45999415237916674</iyy>
          <iyz>0</iyz>
          <izz>0.9091666666666668</izz>
        </inertia>
      </inertial>
    </link>
    
    <!-- Propeller joint: Using submarine configuration -->
    <joint name="propeller_joint" type="revolute">
      <pose>0 0 0 0 0 0</pose>
      <parent>base_link</parent>
      <child>propeller</child>
      <axis>
        <xyz>0 0 1</xyz>
        <use_parent_model_frame>1</use_parent_model_frame>
        <limit>
          <lower>-1e+12</lower>
          <upper>1e+12</upper>
          <effort>-1</effort>
          <velocity>-1</velocity>
        </limit>
        <dynamics>
          <damping>0.05</damping>
          <friction>0.01</friction>
        </dynamics>
      </axis>
    </joint>
    
    <!-- Plugins for joint force and hydrodynamic forces -->
    <plugin
      filename="gz-sim-apply-joint-force-system"
      name="gz::sim::systems::ApplyJointForce">
      <joint_name>propeller_joint</joint_name>
    </plugin>
    
    <plugin
      filename="gz-sim-lift-drag-system"
      name="gz::sim::systems::LiftDrag">
      <air_density>1000</air_density>
      <cla>1.2535816618911175</cla>
      <cla_stall>-1.4326647564469914</cla_stall>
      <cda>0</cda>
      <cda_stall>1.4326647564469914</cda_stall>
      <alpha_stall>1.396</alpha_stall>
      <a0>0</a0>
      <area>0.27637</area>
      <upward>0 -0.7071067811865476 -0.7071067811865475</upward>
      <forward>0 -0.7071067811865475 0.7071067811865476</forward>
      <link_name>propeller</link_name>
      <cp>0.35 0 0</cp>
    </plugin>
    <plugin
      filename="gz-sim-lift-drag-system"
      name="gz::sim::systems::LiftDrag">
      <air_density>1000</air_density>
      <cla>1.2535816618911175</cla>
      <cla_stall>-1.4326647564469914</cla_stall>
      <cda>0</cda>
      <cda_stall>1.4326647564469914</cda_stall>
      <alpha_stall>1.396</alpha_stall>
      <a0>0</a0>
      <area>0.27637</area>
      <upward>-0.7071067811865475 0 -0.7071067811865476</upward>
      <forward>-0.7071067811865476 0 0.7071067811865475</forward>
      <link_name>propeller</link_name>
      <cp>0 -0.35 0</cp>
    </plugin>
    <plugin
      filename="gz-sim-lift-drag-system"
      name="gz::sim::systems::LiftDrag">
      <air_density>1000</air_density>
      <cla>1.2535816618911175</cla>
      <cla_stall>-1.4326647564469914</cla_stall>
      <cda>0</cda>
      <cda_stall>1.4326647564469914</cda_stall>
      <alpha_stall>1.396</alpha_stall>
      <a0>0</a0>
      <area>0.27637</area>
      <upward>0 0.7071067811865475 -0.7071067811865476</upward>
      <forward>0 -0.7071067811865476 -0.7071067811865475</forward>
      <link_name>propeller</link_name>
      <cp>-0.35 0 0</cp>
    </plugin>
  </model>
</sdf>
